
# Try and catch debugging

“Try and catch” is a common programming paradigm found in many programming languages, not just Python. It’s a way to handle runtime errors (or “exceptions”) gracefully without crashing the program.

In Python, the “try and catch” mechanism is implemented using `try` and `except` blocks. When you anticipate that a certain segment of your code might produce an error, you enclose it within a `try` block. Following this block, one or more `except` blocks can be defined to catch specific exceptions.

For example, in the code below, attempting to divide by zero raises a `ZeroDivisionError`.

```python
try:
    # Code that might raise an exception
    result = 10 / 0
except ZeroDivisionError:
    print("Oops! You tried to divide by zero.")
```

Python evaluates the code inside the `try` block, and if an exception occurs, it immediately exits the block and enters the corresponding `except` block. In this example, instead of crashing the program, the error is caught by the `except` block, and a custom error message is printed.

Each `except` block specifies the type of exception it handles, allowing for differentiated responses to various error types. This can range from logging the error message, retrying the operation, or even prompting the user for alternative input.

## Why use try and catch debugging

Wrapping potentially problematic code using `try` and `except` blocks can help you debug in a number of ways:

- **Identify problems**: By wrapping potentially problematic code in a `try` block, you can catch and print exceptions, helping to pinpoint which sections of your code are problematic.
- **Gain insight**: When an exception is caught, you can access its message and type, providing insights into the nature of the error.
- **Fail gracefully**: Like in the example code above, instead of crashing the entire application, you can provide users with a friendly error message or take alternative actions when an exception is raised.
- **Log errors**: Combined with Python’s logging module, exceptions can be logged for further analysis.

Let’s look at another example, this time debugging a function using `try` and `except`. Consider a function that takes a list of numbers and calculates the average:

```python
def calculate_average(numbers):
    return sum(numbers) / len(numbers)
```

If an empty list is passed to this function, it will raise a `ZeroDivisionError`. Using `try` and `except`, you can handle this gracefully:

```python
def calculate_average(numbers):
    try:
        return sum(numbers) / len(numbers)
    except ZeroDivisionError:
        print("The list is empty. Cannot calculate the average.")
        return None
```

Now, instead of the program crashing when passed an empty list, it informs the user of the issue and returns `None`. But what if we need to generate more descriptive messages to help us better understand the error?

## Getting more detailed information

Exceptions in Python are objects. When an exception occurs, it can be beneficial to print or log the exception object itself, as it can provide detailed information about the issue. Fortunately, we can use the `raise` keyword within `except` blocks to raise custom or built-in exceptions with more descriptive messages.

Additionally, we can define our own custom exceptions to provide more specific feedback about errors. For instance, instead of returning `None` or a generic error message, we can raise an exception that provides detailed information about the nature of the error.

Here’s an example:

```python
class InvalidInputError(Exception):
    pass

class EmptyInputError(Exception):
    pass

def calculate_average(numbers):
    try:
        return sum(numbers) / len(numbers)
    except TypeError:
        raise InvalidInputError(f"Expected a list or tuple, but got {type(numbers)}")
    except ZeroDivisionError:
        raise EmptyInputError("The list is empty. Cannot calculate the average.")
    finally:
        print("Execution of calculate_average function completed.")
```

In this example, we’ve defined two custom exceptions: `InvalidInputError` and `EmptyInputError`. When an error occurs, we raise the appropriate exception with a descriptive message. And by using the `finally` clause, we can specify actions that should take place regardless of whether an exception was raised or not.

For more about using `raise`, `except`, and `finally` please review the Python documentation [Errors and Exceptions](https://docs.python.org/3/tutorial/errors.html#defining-clean-up-actions).

## When to use try and catch debugging

While `try` and `except` blocks don’t “debug” in the traditional sense of stepping through code or setting breakpoints, they provide a framework to handle, understand, and ultimately resolve errors in a controlled and informed manner.

That said, while “try and catch” is a widely accepted best practice for handling exceptions, it’s essential to use it judiciously. Overusing it can lead to “swallowing” exceptions, where errors are caught but not adequately handled or logged, leading to silent failures.

Proper exception handling involves not just catching exceptions but also taking appropriate action, whether that’s logging the error, informing the user, or attempting a recovery action.

## Key takeaways

- Try and catch debugging allows developers to identify, log, and handle errors.
- Using `try` and `except` blocks in Python is a powerful way to handle exceptions and improve the debugging process.
- Use the `raise` keyword within `except` blocks to raise custom or built-in exceptions with more descriptive messages.
- Use try and catch debugging judiciously and ensure that exceptions are properly handled with appropriate action.

## Resources for more information

[Python Docs: Built-in Exceptions](https://docs.python.org/3/library/exceptions.html)
